(dp1
S'output'
p2
S'<type \'exceptions.RuntimeError\'> Failure to connect, tried 5 times:\nTraceback (most recent call last):\n  File "F:\\JUSTICEHALL\\study\\develop\\codetrain\\web\\project\\web2py\\gluon\\packages\\dal\\pydal\\base.py", line 454, in __init__\n    self._adapter = adapter(**kwargs)\n  File "F:\\JUSTICEHALL\\study\\develop\\codetrain\\web\\project\\web2py\\gluon\\packages\\dal\\pydal\\adapters\\__init__.py", line 40, in __call__\n    obj = super(AdapterMeta, cls).__call__(*args, **kwargs)\n  File "F:\\JUSTICEHALL\\study\\develop\\codetrain\\web\\project\\web2py\\gluon\\packages\\dal\\pydal\\adapters\\base.py", line 368, in __init__\n    super(SQLAdapter, self).__init__(*args, **kwargs)\n  File "F:\\JUSTICEHALL\\study\\develop\\codetrain\\web\\project\\web2py\\gluon\\packages\\dal\\pydal\\adapters\\base.py", line 50, in __init__\n    self._initialize_(do_connect)\n  File "F:\\JUSTICEHALL\\study\\develop\\codetrain\\web\\project\\web2py\\gluon\\packages\\dal\\pydal\\adapters\\sqlite.py", line 25, in _initialize_\n    self.dbpath = self.uri.split(\'://\', 1)[1]\nIndexError: list index out of range\n'
p3
sS'layer'
p4
S'F:\\JUSTICEHALL\\study\\develop\\codetrain\\web\\project\\web2py\\applications\\splitnote\\models\\db.py'
p5
sS'code'
p6
S'<code object <module> at 047E3CC8, file "F:\\JUSTICEHALL\\study\\develop\\codetrain\\web\\project\\web2py\\applications\\splitnote\\models\\db.py", line 1>'
p7
sS'snapshot'
p8
(dp9
sS'traceback'
p10
S'Traceback (most recent call last):\n  File "F:\\JUSTICEHALL\\study\\develop\\codetrain\\web\\project\\web2py\\gluon\\restricted.py", line 219, in restricted\n    exec(ccode, environment)\n  File "F:\\JUSTICEHALL\\study\\develop\\codetrain\\web\\project\\web2py\\applications\\splitnote\\models\\db.py", line 13, in <module>\n    usersdb = DAL(\'sqlite:\\\\newusers.db\')\n  File "F:\\JUSTICEHALL\\study\\develop\\codetrain\\web\\project\\web2py\\gluon\\packages\\dal\\pydal\\base.py", line 169, in __call__\n    obj = super(MetaDAL, cls).__call__(*args, **kwargs)\n  File "F:\\JUSTICEHALL\\study\\develop\\codetrain\\web\\project\\web2py\\gluon\\packages\\dal\\pydal\\base.py", line 474, in __init__\n    "Failure to connect, tried %d times:\\n%s" % (attempts, tb)\nRuntimeError: Failure to connect, tried 5 times:\nTraceback (most recent call last):\n  File "F:\\JUSTICEHALL\\study\\develop\\codetrain\\web\\project\\web2py\\gluon\\packages\\dal\\pydal\\base.py", line 454, in __init__\n    self._adapter = adapter(**kwargs)\n  File "F:\\JUSTICEHALL\\study\\develop\\codetrain\\web\\project\\web2py\\gluon\\packages\\dal\\pydal\\adapters\\__init__.py", line 40, in __call__\n    obj = super(AdapterMeta, cls).__call__(*args, **kwargs)\n  File "F:\\JUSTICEHALL\\study\\develop\\codetrain\\web\\project\\web2py\\gluon\\packages\\dal\\pydal\\adapters\\base.py", line 368, in __init__\n    super(SQLAdapter, self).__init__(*args, **kwargs)\n  File "F:\\JUSTICEHALL\\study\\develop\\codetrain\\web\\project\\web2py\\gluon\\packages\\dal\\pydal\\adapters\\base.py", line 50, in __init__\n    self._initialize_(do_connect)\n  File "F:\\JUSTICEHALL\\study\\develop\\codetrain\\web\\project\\web2py\\gluon\\packages\\dal\\pydal\\adapters\\sqlite.py", line 25, in _initialize_\n    self.dbpath = self.uri.split(\'://\', 1)[1]\nIndexError: list index out of range\n\n'
p11
s.